<?xml version="1.0"?>
<robot name="Motoman_GP180">
  <material name="MotomanBlue">
    <color rgba="0.12941 0.14902 0.74902 1" />
  </material>

  <!-- link list -->
  <link name="base_link">
    <visual>
      <origin xyz="0 0 0" rpy="0 0 0" />
      <geometry>
        <mesh filename="../Visual/BaseLink.stl" />
      </geometry>
      <material name="MotomanBlue" />
    </visual>
    <collision>
      <origin xyz="0 0 0" rpy="0 0 0" />
      <geometry>
        <mesh filename="../Collision/BaseLink.stl" />
      </geometry>
    </collision>
  </link>
  <link name="Link1">
    <visual>
      <origin xyz="0 0 -0.65" rpy="0 0 0" />
      <geometry>
        <mesh filename="../Visual/Link1.stl" />
      </geometry>
      <material name="MotomanBlue" />
    </visual>
    <collision>
      <origin xyz="0 0 -0.65" rpy="0 0 0" />
      <geometry>
        <mesh filename="../Collision/Link1.stl" />
      </geometry>
    </collision>
  </link>
  <link name="Link2">
    <visual>
      <origin xyz="-0.325 0 -0.65" rpy="0 0 0" />
      <geometry>
        <mesh filename="../Visual/Link2.stl" />
      </geometry>
      <material name="MotomanBlue" />
    </visual>
    <collision>
      <origin xyz="-0.325 0 -0.65" rpy="0 0 0" />
      <geometry>
        <mesh filename="../Collision/Link2.stl" />
      </geometry>
    </collision>
  </link>
  <link name="Link3">
    <visual>
      <origin xyz="-0.325 0 -1.8" rpy="0 0 0" />
      <geometry>
        <mesh filename="../Visual/Link3.stl" />
      </geometry>
      <material name="MotomanBlue" />
    </visual>
    <collision>
      <origin xyz="-0.325 0 -1.8" rpy="0 0 0" />
      <geometry>
        <mesh filename="../Collision/Link3.stl" />
      </geometry>
    </collision>
  </link>
  <link name="Link4">
    <visual>
      <origin xyz="-0.325 0 -2.1" rpy="0 0 0" />
      <geometry>
        <mesh filename="../Visual/Link4.stl" />
      </geometry>
      <material name="MotomanBlue" />
    </visual>
    <collision>
      <origin xyz="-0.325 0 -2.1" rpy="0 0 0" />
      <geometry>
        <mesh filename="../Collision/Link4.stl" />
      </geometry>
    </collision>
  </link>
  <link name="Link5">
    <visual>
      <origin xyz="-1.55 0 -2.1" rpy="0 0 0" />
      <geometry>
        <mesh filename="../Visual/Link5.stl" />
      </geometry>
      <material name="MotomanBlue" />
    </visual>
    <collision>
      <origin xyz="-1.55 0 -2.1" rpy="0 0 0" />
      <geometry>
        <mesh filename="../Collision/Link5.stl" />
      </geometry>
    </collision>
  </link>
  <link name="Link6">
    <visual>
      <origin xyz="-1.775 0 -2.1" rpy="0 0 0" />
      <geometry>
        <mesh filename="../Visual/Link6.stl" />
      </geometry>
      <material name="MotomanBlue" />
    </visual>
    <collision>
      <origin xyz="-1.775 0 -2.1" rpy="0 0 0" />
      <geometry>
        <mesh filename="../Collision/Link6.stl" />
      </geometry>
    </collision>
  </link>
  <link name="ee_link" />
  <!-- end of link list -->

  <!-- joint list -->
  <joint name="Joint1" type="revolute">
    <parent link="base_link" />
    <child link="Link1" />
    <origin rpy="0 0 0" xyz="0 0 0.650" />
    <axis xyz="0 0 1" />
    <limit lower="-3.1415926" upper="3.1415926" velocity="2.181661" />
  </joint>
  <joint name="Joint2" type="revolute">
    <parent link="Link1" />
    <child link="Link2" />
    <origin rpy="0 0 0" xyz="0.325 0 0" />
    <axis xyz="0 1 0" />
    <limit lower="-1.047197" upper="1.3264" velocity="2.0071286" />
  </joint>
  <joint name="Joint3" type="revolute">
    <parent link="Link2" />
    <child link="Link3" />
    <origin rpy="0 0 0" xyz="0 0 1.15" />
    <axis xyz="0 -1 0" />
    <limit lower="-1.500983" upper="1.570796" velocity="2.181661" />
  </joint>
  <joint name="Joint4" type="revolute">
    <parent link="Link3" />
    <child link="Link4" />
    <origin rpy="0 0 0" xyz="0 0 0.3" />
    <axis xyz="-1 0 0" />
    <limit lower="-6.283185" upper="6.283185" velocity="3.176499" />
  </joint>
  <joint name="Joint5" type="revolute">
    <parent link="Link4" />
    <child link="Link5" />
    <origin rpy="0 0 0" xyz="1.225 0 0" />
    <axis xyz="0 -1 0" />
    <limit lower="-2.2689280" upper="2.2689280" velocity="3.054326" />
  </joint>
  <joint name="Joint6" type="revolute">
    <parent link="Link5" />
    <child link="Link6" />
    <origin rpy="0 0 0" xyz="0.225 0 0" />
    <axis xyz="-1 0 0" />
    <limit lower="-6.2831853" upper="6.2831853" velocity="4.62512" />
  </joint>
  <joint name="jointEE" type="fixed">
    <origin rpy="3.1415926 -1.570796 0" xyz="0 0 0" />
    <parent link="Link6" />
    <child link="ee_link" />
  </joint>
  <!-- end of joint list -->

</robot>
