<?xml version='1.0' encoding='utf-8'?>
<robot name="ABB_IRB2400_12_155">
	<material name="ABBOrange">
		<color rgba="0.737 0.349 0.161 1.000" />
	</material>
	<material name="ABBBlack">
		<color rgba="0.188 0.196 0.204 1.000" />
	</material>

	<!-- link list -->
	<link name="base_link">
		<visual>
			<origin rpy="0.000 -0.000 0.000" xyz="0.000 0.000 0.000" />
			<geometry>
				<mesh filename="Visual/BaseLink.dae" />
			</geometry>
		</visual>
		<collision>
			<origin rpy="0.000 -0.000 0.000" xyz="0.000 0.000 0.000" />
			<geometry>
				<mesh filename="Collision/BaseLink.stl" />
			</geometry>
		</collision>
	</link>
	<link name="Link1">
		<visual>
			<origin rpy="0.000 -0.000 0.000" xyz="0.000 0.000 0.000" />
			<geometry>
				<mesh filename="Visual/Link1.dae" />
			</geometry>
		</visual>
		<collision>
			<origin rpy="0.000 -0.000 0.000" xyz="0.000 0.000 0.000" />
			<geometry>
				<mesh filename="Collision/Link1.stl" />
			</geometry>
		</collision>
	</link>
	<link name="Link2">
		<visual>
			<origin rpy="0.000 -0.000 0.000" xyz="0.000 0.000 0.000" />
			<geometry>
				<mesh filename="Visual/Link2.dae" />
			</geometry>
		</visual>
		<collision>
			<origin rpy="0.000 -0.000 0.000" xyz="0.000 0.000 0.000" />
			<geometry>
				<mesh filename="Collision/Link2.stl" />
			</geometry>
		</collision>
	</link>
	<link name="Link3">
		<visual>
			<origin rpy="0.000 -0.000 0.000" xyz="0.000 0.000 0.000" />
			<geometry>
				<mesh filename="Visual/Link3.dae" />
			</geometry>
		</visual>
		<collision>
			<origin rpy="0.000 -0.000 0.000" xyz="0.000 0.000 0.000" />
			<geometry>
				<mesh filename="Collision/Link3.stl" />
			</geometry>
		</collision>
	</link>
	<link name="Link4">
		<visual>
			<origin rpy="0.000 -0.000 0.000" xyz="0.000 0.000 0.000" />
			<geometry>
				<mesh filename="Visual/Link4.dae" />
			</geometry>
		</visual>
		<collision>
			<origin rpy="0.000 -0.000 0.000" xyz="0.000 0.000 0.000" />
			<geometry>
				<mesh filename="Collision/Link4.stl" />
			</geometry>
		</collision>
	</link>
	<link name="Link5">
		<visual>
			<origin rpy="0.000 -0.000 0.000" xyz="0.000 0.000 0.000" />
			<geometry>
				<mesh filename="Visual/Link5.dae" />
			</geometry>
		</visual>
		<collision>
			<origin rpy="0.000 -0.000 0.000" xyz="0.000 0.000 0.000" />
			<geometry>
				<mesh filename="Collision/Link5.stl" />
			</geometry>
		</collision>
	</link>
	<link name="Link6">
		<visual>
			<origin rpy="0.000 -0.000 0.000" xyz="0.000 0.000 0.000" />
			<geometry>
				<mesh filename="Visual/Link6.dae" />
			</geometry>
		</visual>
		<collision>
			<origin rpy="0.000 -0.000 0.000" xyz="0.000 0.000 0.000" />
			<geometry>
				<mesh filename="Collision/Link6.stl" />
			</geometry>
		</collision>
	</link>
	<link name="LinkLever_1">
		<visual>
			<origin rpy="0.000 -0.000 0.000" xyz="0.000 0.000 0.000" />
			<geometry>
				<mesh filename="Visual/LinkLever_1.dae" />
			</geometry>
		</visual>
		<collision>
			<origin rpy="0.000 -0.000 0.000" xyz="0.000 0.000 0.000" />
			<geometry>
				<mesh filename="Collision/LinkLever_1.stl" />
			</geometry>
		</collision>
	</link>
	<link name="LinkLever_2">
		<visual>
			<origin rpy="0.000 -0.000 0.000" xyz="0.000 0.000 0.000" />
			<geometry>
				<mesh filename="Visual/LinkLever_2.dae" />
			</geometry>
		</visual>
		<collision>
			<origin rpy="0.000 -0.000 0.000" xyz="0.000 0.000 0.000" />
			<geometry>
				<mesh filename="Collision/LinkLever_2.stl" />
			</geometry>
		</collision>
	</link>
	<link name="ee_link" />
    <!-- end of link list -->

    <!-- joint list -->
	<joint name="Joint1" type="revolute">
		<axis xyz="0.000 0.000 1.000" />
		<parent link="base_link" />
		<child link="Link1" />
		<origin rpy="0.000 -0.000 0.000" xyz="0.000 0.000 0.000" />
		<limit acceleration="13.09" effort="0.0" lower="-3.1216" upper="3.1216" velocity="2.618" />
	</joint>
	<joint name="Joint2" type="revolute">
		<axis xyz="0.000 1.000 0.000" />
		<parent link="Link1" />
		<child link="Link2" />
		<origin rpy="0.000 -0.000 0.000" xyz="0.100 0.000 0.615" />
		<limit acceleration="13.09" effort="0.0" lower="-1.7253" upper="1.8999" velocity="2.618" />
	</joint>
	<joint name="Joint3" type="revolute">
		<axis xyz="0.000 1.000 0.000" />
		<parent link="Link2" />
		<child link="Link3" />
		<origin rpy="0.000 -0.000 0.000" xyz="0.000 0.000 0.705" />
		<limit acceleration="13.09" effort="0.0" lower="-1.0272" upper="1.1145" velocity="2.618" />
	</joint>
	<joint name="Joint4" type="revolute">
		<axis xyz="1.000 0.000 0.000" />
		<parent link="Link3" />
		<child link="Link4" />
		<origin rpy="0.000 -0.000 0.000" xyz="0.000 0.000 0.135" />
		<limit acceleration="31.416" effort="0.0" lower="-3.47" upper="3.47" velocity="6.2832" />
	</joint>
	<joint name="Joint5" type="revolute">
		<axis xyz="0.000 1.000 0.000" />
		<parent link="Link4" />
		<child link="Link5" />
		<origin rpy="0.000 -0.000 0.000" xyz="0.755 0.000 0.000" />
		<limit acceleration="31.416" effort="0.0" lower="-2.0744" upper="2.0744" velocity="6.2832" />
	</joint>

	<joint name="Joint6" type="revolute">
		<axis xyz="1.000 0.000 0.000" />
		<parent link="Link5" />
		<child link="Link6" />
		<origin rpy="0.000 -0.000 0.000" xyz="0.000 0.000 0.000" />
		<limit acceleration="39.27" effort="0.0" lower="-6.9613" upper="6.96130" velocity="7.854" />
	</joint>
	<joint name="JointLever_1" type="continuous">
		<axis xyz="0.000 1.000 0.000" />
		<parent link="Link2" />
		<child link="LinkLever_1" />
		<origin rpy="0.000 -0.000 0.000" xyz="0.000 0.000 0.000" />
		<mimic joint="Joint3" multiplier="1.0" offset="0.0" />
		<limit acceleration="0.0" effort="0.0" lower="-3.1415" upper="3.14159" velocity="0.0" />
	</joint>
	<joint name="JointLever_2" type="continuous">
		<axis xyz="0.000 1.000 0.000" />
		<parent link="Link3" />
		<child link="LinkLever_2" />
		<origin rpy="0.000 -0.000 0.000" xyz="-0.180 0.000 0.000" />
		<mimic joint="Joint3" multiplier="-1.0" offset="0.0" />
		<limit acceleration="0.0" effort="0.0" lower="-3.1415" upper="3.14159" velocity="0.0" />
	</joint>

	<joint name="jointEE" type="fixed">
		<parent link="Link6" />
		<child link="ee_link" />
		<origin rpy="0.000 1.570796327 0.000" xyz="0.085 0.000 0.000" />
	</joint>
    <!-- end of joint list -->

</robot>