<?xml version="1.0"?>
<robot name="UniversalRobots_UR10">
  <!-- link list -->
  <link name="base_link">
    <visual>
      <geometry>
        <mesh filename="Visual/BaseLink.dae" />
      </geometry>
      <material name="LightGrey">
        <color rgba="0.7 0.7 0.7 1.0" />
      </material>
    </visual>
    <collision>
      <geometry>
        <mesh filename="Collision/BaseLink.stl" />
      </geometry>
    </collision>
    <inertial>
      <mass value="4.0" />
      <origin rpy="0 0 0" xyz="0.0 0.0 0.0" />
      <inertia ixx="0.0061063308908" ixy="0.0" ixz="0.0" iyy="0.0061063308908" iyz="0.0" izz="0.01125" />
    </inertial>
  </link>
  <link name="Link1">
    <visual>
      <geometry>
        <mesh filename="Visual/Link1.dae" />
      </geometry>
      <material name="LightGrey">
        <color rgba="0.7 0.7 0.7 1.0" />
      </material>
    </visual>
    <collision>
      <geometry>
        <mesh filename="Collision/Link1.stl" />
      </geometry>
    </collision>
    <inertial>
      <mass value="7.778" />
      <origin rpy="0 0 0" xyz="0.0 0.0 0.0" />
      <inertia ixx="0.0314743125769" ixy="0.0" ixz="0.0" iyy="0.0314743125769" iyz="0.0" izz="0.021875625" />
    </inertial>
  </link>
  <link name="Link2">
    <visual>
      <geometry>
        <mesh filename="Visual/Link2.dae" />
      </geometry>
      <material name="LightGrey">
        <color rgba="0.7 0.7 0.7 1.0" />
      </material>
    </visual>
    <collision>
      <geometry>
        <mesh filename="Collision/Link2.stl" />
      </geometry>
    </collision>
    <inertial>
      <mass value="12.93" />
      <origin rpy="0 0 0" xyz="0.0 -0.045 0.306" />
      <inertia ixx="0.421753803798" ixy="0.0" ixz="0.0" iyy="0.421753803798" iyz="0.0" izz="0.036365625" />
    </inertial>
  </link>
  <link name="Link3">
    <visual>
      <geometry>
        <mesh filename="Visual/Link3.dae" />
      </geometry>
      <material name="LightGrey">
        <color rgba="0.7 0.7 0.7 1.0" />
      </material>
    </visual>
    <collision>
      <geometry>
        <mesh filename="Collision/Link3.stl" />
      </geometry>
    </collision>
    <inertial>
      <mass value="3.87" />
      <origin rpy="0 0 0" xyz="0.0 0.0 0.28615" />
      <inertia ixx="0.111069694097" ixy="0.0" ixz="0.0" iyy="0.111069694097" iyz="0.0" izz="0.010884375" />
    </inertial>
  </link>
  <link name="Link4">
    <visual>
      <geometry>
        <mesh filename="Visual/Link4.dae" />
      </geometry>
      <material name="LightGrey">
        <color rgba="0.7 0.7 0.7 1.0" />
      </material>
    </visual>
    <collision>
      <geometry>
        <mesh filename="Collision/Link4.stl" />
      </geometry>
    </collision>
    <inertial>
      <mass value="1.96" />
      <origin rpy="0 0 0" xyz="0.0 0.1149 0.0" />
      <inertia ixx="0.0051082479567" ixy="0.0" ixz="0.0" iyy="0.0051082479567" iyz="0.0" izz="0.0055125" />
    </inertial>
  </link>
  <link name="Link5">
    <visual>
      <geometry>
        <mesh filename="Visual/Link5.dae" />
      </geometry>
      <material name="LightGrey">
        <color rgba="0.7 0.7 0.7 1.0" />
      </material>
    </visual>
    <collision>
      <geometry>
        <mesh filename="Collision/Link5.stl" />
      </geometry>
    </collision>
    <inertial>
      <mass value="1.96" />
      <origin rpy="0 0 0" xyz="0.0 0.0 0.1157" />
      <inertia ixx="0.0051082479567" ixy="0.0" ixz="0.0" iyy="0.0051082479567" iyz="0.0" izz="0.0055125" />
    </inertial>
  </link>
  <link name="Link6">
    <visual>
      <geometry>
        <mesh filename="Visual/Link6.dae" />
      </geometry>
      <material name="LightGrey">
        <color rgba="0.7 0.7 0.7 1.0" />
      </material>
    </visual>
    <collision>
      <geometry>
        <mesh filename="Collision/Link6.stl" />
      </geometry>
    </collision>
    <inertial>
      <mass value="0.202" />
      <origin rpy="1.57079632679 0 0" xyz="0.0 0.07695 0.0" />
      <inertia ixx="0.000117921661165" ixy="0.0" ixz="0.0" iyy="0.000117921661165" iyz="0.0" izz="0.000204525" />
    </inertial>
  </link>
  <link name="ee_link" />
  <!-- end of link list -->

  <!-- joint list -->
  <joint name="Joint1" type="revolute">
    <parent link="base_link" />
    <child link="Link1" />
    <origin rpy="0.0 0.0 0.0" xyz="0.0 0.0 0.1273" />
    <axis xyz="0 0 1" />
    <limit effort="330.0" lower="-6.28318530718" upper="6.28318530718" velocity="2.16" />
    <dynamics damping="0.0" friction="0.0" />
  </joint>
  <joint name="Joint2" type="revolute">
    <parent link="Link1" />
    <child link="Link2" />
    <origin rpy="0.0 1.57079632679 0.0" xyz="0.0 0.220941 0.0" />
    <axis xyz="0 1 0" />
    <limit effort="330.0" lower="-6.28318530718" upper="6.28318530718" velocity="2.16" />
    <dynamics damping="0.0" friction="0.0" />
  </joint>
  <joint name="Joint3" type="revolute">
    <parent link="Link2" />
    <child link="Link3" />
    <origin rpy="0.0 0.0 0.0" xyz="0.0 -0.1719 0.612" />
    <axis xyz="0 1 0" />
    <limit effort="150.0" lower="-3.14159265359" upper="3.14159265359" velocity="3.15" />
    <dynamics damping="0.0" friction="0.0" />
  </joint>
  <joint name="Joint4" type="revolute">
    <parent link="Link3" />
    <child link="Link4" />
    <origin rpy="0.0 1.57079632679 0.0" xyz="0.0 0.0 0.5723" />
    <axis xyz="0 1 0" />
    <limit effort="54.0" lower="-6.28318530718" upper="6.28318530718" velocity="3.2" />
    <dynamics damping="0.0" friction="0.0" />
  </joint>
  <joint name="Joint5" type="revolute">
    <parent link="Link4" />
    <child link="Link5" />
    <origin rpy="0.0 0.0 0.0" xyz="0.0 0.1149 0.0" />
    <axis xyz="0 0 1" />
    <limit effort="54.0" lower="-6.28318530718" upper="6.28318530718" velocity="3.2" />
    <dynamics damping="0.0" friction="0.0" />
  </joint>
  <joint name="Joint6" type="revolute">
    <parent link="Link5" />
    <child link="Link6" />
    <origin rpy="0.0 0.0 0.0" xyz="0.0 0.0 0.1157" />
    <axis xyz="0 1 0" />
    <limit effort="54.0" lower="-6.28318530718" upper="6.28318530718" velocity="3.2" />
    <dynamics damping="0.0" friction="0.0" />
  </joint>
  <joint name="jointEE" type="fixed">
    <parent link="Link6" />
    <child link="ee_link" />
    <origin rpy="0.0 0.0 1.57079632679" xyz="0.0 0.0922 0.0" />
  </joint>
  <!-- end of joint list -->

</robot>
