<?xml version="1.0"?>
<robot name="Motoman_MotoMini">
  <material name="MotomanBlue">
    <color rgba="0.12941 0.14902 1 1" />
  </material>

  <!-- link list -->
  <link name="base_link">
    <visual>
      <geometry>
        <mesh filename="../Visual/BaseLink.stl" />
      </geometry>
      <material name="MotomanBlue" />
    </visual>
    <collision>
      <geometry>
        <mesh filename="../Collision/BaseLink.stl" />
      </geometry>
    </collision>
  </link>
  <link name="Link1">
    <visual>
      <geometry>
        <mesh filename="../Visual/Link1.stl" />
      </geometry>
      <material name="MotomanBlue" />
    </visual>
    <collision>
      <geometry>
        <mesh filename="../Collision/Link1.stl" />
      </geometry>
    </collision>
  </link>
  <link name="Link2">
    <visual>
      <geometry>
        <mesh filename="../Visual/Link2.stl" />
      </geometry>
      <material name="MotomanBlue" />
    </visual>
    <collision>
      <geometry>
        <mesh filename="../Collision/Link2.stl" />
      </geometry>
    </collision>
  </link>
  <link name="Link3">
    <visual>
      <geometry>
        <mesh filename="../Visual/Link3.stl" />
      </geometry>
      <material name="MotomanBlue" />
    </visual>
    <collision>
      <geometry>
        <mesh filename="../Collision/Link3.stl" />
      </geometry>
    </collision>
  </link>
  <link name="Link4">
    <visual>
      <geometry>
        <mesh filename="../Visual/Link4.stl" />
      </geometry>
      <material name="MotomanBlue" />
    </visual>
    <collision>
      <geometry>
        <mesh filename="../Collision/Link4.stl" />
      </geometry>
    </collision>
  </link>
  <link name="Link5">
    <visual>
      <geometry>
        <mesh filename="../Visual/Link5.stl" />
      </geometry>
      <material name="MotomanBlue" />
    </visual>
    <collision>
      <geometry>
        <mesh filename="../Collision/Link5.stl" />
      </geometry>
    </collision>
  </link>
  <link name="Link6">
    <visual>
      <geometry>
        <mesh filename="../Visual/Link6.stl" />
      </geometry>
      <material name="MotomanBlue" />
    </visual>
    <collision>
      <geometry>
        <mesh filename="../Collision/Link6.stl" />
      </geometry>
    </collision>
  </link>
  <link name="ee_link" />
  <!-- end of link list -->

  <!-- joint list -->
  <joint name="Joint1" type="revolute">
    <parent link="base_link" />
    <child link="Link1" />
    <origin xyz="0 0 0.103" rpy="0 0 0" />
    <axis xyz="0 0 1" />
    <limit lower="-2.9670" upper="2.9670" effort="0.12" velocity="5.4977" acceleration="25.0" />
  </joint>
  <joint name="Joint2" type="revolute">
    <parent link="Link1" />
    <child link="Link2" />
    <origin xyz="0.020 0 0" rpy="0 0 0" />
    <axis xyz="0 1 0" />
    <limit lower="-1.4835" upper="1.5707" effort="0.12" velocity="5.4977" acceleration="25.0" />
  </joint>
  <joint name="Joint3" type="revolute">
    <parent link="Link2" />
    <child link="Link3" />
    <origin xyz="0 0 0.165" rpy="0 0 0" />
    <axis xyz="0 -1 0" />
    <limit lower="-0.8726" upper="1.5707" effort="0.12" velocity="7.3304" acceleration="35.0" />
  </joint>
  <joint name="Joint4" type="revolute">
    <parent link="Link3" />
    <child link="Link4" />
    <origin xyz="0.165 0 0" rpy="0 0 0" />
    <axis xyz="-1 0 0" />
    <limit lower="-2.4434" upper="2.4434" effort="0.07" velocity="10.4719" acceleration="50.0" />
  </joint>
  <joint name="Joint5" type="revolute">
    <parent link="Link4" />
    <child link="Link5" />
    <origin xyz="0 0 0" rpy="0 0 0" />
    <axis xyz="0 -1 0" />
    <limit lower="-0.5235" upper="3.6651" effort="0.07" velocity="10.4719" acceleration="50.0" />
  </joint>
  <joint name="Joint6" type="revolute">
    <parent link="Link5" />
    <child link="Link6" />
    <origin xyz="0 0 0" rpy="0 0 0" />
    <axis xyz="0 0 1" />
    <limit lower="-6.2831" upper="6.2831" effort="0.07" velocity="10.4719" acceleration="50.0" />
  </joint>
  <joint name="jointEE" type="fixed">
    <origin xyz="0 0 -0.040 " rpy="3.1415926 0 0" />
    <parent link="Link6" />
    <child link="ee_link" />
  </joint>
  <!-- end of joint list -->

</robot>
