<?xml version='1.0' encoding='utf-8'?>
<robot name="Motoman_GP25">
	<material name="MotomanBlue">
		<color rgba="0.12941 0.14902 0.74902 1" />
	</material>
	
    <!-- link list -->
	<link name="base_link">
		<visual name="visual">
			<origin rpy="0.000 -0.000 0.000" xyz="0.000 0.000 0.000" />
			<geometry>
				<mesh filename="Visual/BaseLink.stl" />
			</geometry>
            <material name="MotomanBlue" />
		</visual>
		<collision name="collision">
			<origin rpy="0.000 -0.000 0.000" xyz="0.000 0.000 0.000" />
			<geometry>
				<mesh filename="Collision/BaseLink.stl" />
			</geometry>
		</collision>
	</link>
	<link name="Link1">
		<visual name="visual">
			<origin rpy="0.000 -0.000 0.000" xyz="0.000 0.000 0.000" />
			<geometry>
				<mesh filename="Visual/Link1.stl" />
			</geometry>
            <material name="MotomanBlue" />
		</visual>
		<collision name="collision">
			<origin rpy="0.000 -0.000 0.000" xyz="0.000 0.000 0.000" />
			<geometry>
				<mesh filename="Collision/Link1.stl" />
			</geometry>
		</collision>
	</link>
	<link name="Link2">
		<visual name="visual">
			<origin rpy="0.000 -0.000 0.000" xyz="0.000 0.000 0.000" />
			<geometry>
				<mesh filename="Visual/Link2.stl" />
			</geometry>
			<material name="MotomanBlue" />
		</visual>
		<collision name="collision">
			<origin rpy="0.000 -0.000 0.000" xyz="0.000 0.000 0.000" />
			<geometry>
				<mesh filename="Collision/Link2.stl" />
			</geometry>
		</collision>
	</link>
	<link name="Link3">
		<visual name="visual">
			<origin rpy="0.000 -0.000 0.000" xyz="0.000 0.000 0.000" />
			<geometry>
				<mesh filename="Visual/Link3.stl" />
			</geometry>
			<material name="MotomanBlue" />
		</visual>
		<collision name="collision">
			<origin rpy="0.000 -0.000 0.000" xyz="0.000 0.000 0.000" />
			<geometry>
				<mesh filename="Collision/Link3.stl" />
			</geometry>
		</collision>
	</link>
	<link name="Link4">
		<visual name="visual">
			<origin rpy="0.000 -0.000 0.000" xyz="0.000 0.000 0.000" />
			<geometry>
				<mesh filename="Visual/Link4.stl" />
			</geometry>
			<material name="MotomanBlue" />
		</visual>
		<collision name="collision">
			<origin rpy="0.000 -0.000 0.000" xyz="0.000 0.000 0.000" />
			<geometry>
				<mesh filename="Collision/Link4.stl" />
			</geometry>
		</collision>
	</link>
	<link name="Link5">
		<visual name="visual">
			<origin rpy="0.000 -0.000 0.000" xyz="0.000 0.000 0.000" />
			<geometry>
				<mesh filename="Visual/Link5.stl" />
			</geometry>
			<material name="MotomanBlue" />
		</visual>
		<collision name="collision">
			<origin rpy="0.000 -0.000 0.000" xyz="0.000 0.000 0.000" />
			<geometry>
				<mesh filename="Collision/Link5.stl" />
			</geometry>
		</collision>
	</link>
	<link name="Link6">
		<visual name="visual">
			<origin rpy="0.000 -0.000 0.000" xyz="0.000 0.000 0.000" />
			<geometry>
				<mesh filename="Visual/Link6.stl" />
			</geometry>
			<material name="MotomanBlue" />
		</visual>
		<collision name="collision">
			<origin rpy="0.000 -0.000 0.000" xyz="0.000 0.000 0.000" />
			<geometry>
				<mesh filename="Collision/Link6.stl" />
			</geometry>
		</collision>
	</link>
	<link name="ee_link" />
    <!-- end of link list -->

    <!-- joint list -->
	<joint name="Joint1" type="revolute">
		<axis xyz="0.000 0.000 1.000" />
		<parent link="base_link" />
		<child link="Link1" />
		<origin rpy="0.000 -0.000 0.000" xyz="0.000 0.000 0.505" />
		<limit acceleration="18.3259" effort="3087.0" lower="-3.1215" upper="3.12159" velocity="3.66519" />
	</joint>
	<joint name="Joint2" type="revolute">
		<axis xyz="0.000 1.000 0.000" />
		<parent link="Link1" />
		<child link="Link2" />
		<origin rpy="0.000 -0.000 0.000" xyz="0.150 0.000 0.000" />
		<limit acceleration="18.3259" effort="3087.0" lower="-1.8125" upper="2.68526" velocity="3.66519" />
	</joint>
	<joint name="Joint3" type="revolute">
		<axis xyz="0.000 -1.000 0.000" />
		<parent link="Link2" />
		<child link="Link3" />
		<origin rpy="0.000 -0.000 0.000" xyz="0.000 0.000 0.760" />
		<limit acceleration="23.1256" effort="926.1" lower="-1.4809" upper="2.77252" velocity="4.62512" />
	</joint>
	<joint name="Joint4" type="revolute">
		<axis xyz="-1.000 0.000 0.000" />
		<parent link="Link3" />
		<child link="Link4" />
		<origin rpy="0.000 -0.000 0.000" xyz="0.000 0.000 0.200" />
		<limit acceleration="36.6519" effort="88.2" lower="-3.4706" upper="3.47065" velocity="7.33038" />
	</joint>
	<joint name="Joint5" type="revolute">
		<axis xyz="0.000 -1.000 0.000" />
		<parent link="Link4" />
		<child link="Link5" />
		<origin rpy="0.000 -0.000 0.000" xyz="0.795 0.000 0.000" />
		<limit acceleration="36.6519" effort="70.56" lower="-2.6852" upper="2.59799" velocity="7.33038" />
	</joint>
	<joint name="Joint6" type="revolute">
		<axis xyz="-1.000 0.000 0.000" />
		<parent link="Link5" />
		<child link="Link6" />
		<origin rpy="0.000 -0.000 0.000" xyz="0.000 0.000 0.000" />
		<limit acceleration="77.2308" effort="50.31" lower="-7.9212" upper="7.92124" velocity="15.4461" />
	</joint>

	<joint name="jointEE" type="fixed">
		<parent link="Link6" />
		<child link="ee_link" />
		<origin rpy="3.141592654 -1.570796327 0.000" xyz="0.1000 0.000 0.000" />
	</joint>
    <!-- end of joint list -->

</robot>