<?xml version="1.0" ?>
<!--FOR GRIPPER, THERE IS NO LINK INERTIA DEFINED HERE-->
<robot name="engraver">
  <link name="base">
    <visual>
      <geometry>
        <mesh filename="base.obj"/>
      </geometry>
    </visual>
  </link>
  <joint name="joint0" type="prismatic">
    <parent link="base"/>
    <child link="axis_y"/>
    <origin rpy="0.0 0.0 0.0" xyz="0 0 0"/>
    <limit effort="100" lower="0.00" upper="0.02" velocity="0.2"/>
  </joint>
  <link name="axis_y">
    <visual>
      <geometry>
        <mesh filename="axis_y.obj"/>
      </geometry>
    </visual>
  </link>
  <joint name="joint1" type="prismatic">
    <parent link="axis_y"/>
    <child link="axis_x"/>
    <origin rpy="0.0 0.0 0.0" xyz="0 0 0"/>
    <limit effort="100" lower="0.00" upper="0.02" velocity="0.2"/>
  </joint>
  <link name="axis_x">
    <visual>
      <geometry>
        <mesh filename="axis_x.obj"/>
      </geometry>
    </visual>
  </link>
  <joint name="joint2" type="prismatic">
    <parent link="axis_x"/>
    <child link="axis_z"/>
    <origin rpy="0.0 0.0 0.0" xyz="0 0 0"/>
    <limit effort="100" lower="0.00" upper="0.02" velocity="0.2"/>
  </joint>
  <link name="axis_z">
    <visual>
      <geometry>
        <mesh filename="axis_z.obj"/>
      </geometry>
    </visual>
  </link>
  <joint name="joint3" type="fixed">
    <parent link="axis_z"/>
    <child link="laser_head"/>
    <origin rpy="0.0 0.0 0.0" xyz="0 0 0"/>
    <limit effort="100" lower="0.00" upper="0.02" velocity="0.2"/>
  </joint>
  <link name="laser_head">
    <visual>
      <geometry>
        <mesh filename="laser_head.obj"/>
      </geometry>
    </visual>
  </link>
</robot>
