<?xml version='1.0' encoding='utf-8'?>
<robot name="ABB_IRB4400L_30_243">
	<material name="ABBBlack">
		<color rgba="0.188 0.196 0.204 1.000" />
	</material>
	<material name="ABBWhite">
		<color rgba="0.9254902 0.9254902 0.9058824 1" />
	</material>

    <!-- link list -->
	<link name="base_link">
		<visual>
			<origin rpy="0.000 -0.000 0.000" xyz="0.000 0.000 0.000" />
			<geometry>
				<mesh filename="../Visual/BaseLink.stl" />
			</geometry>
			<material name="ABBWhite" />
		</visual>
		<collision>
			<origin rpy="0.000 -0.000 0.000" xyz="0.000 0.000 0.000" />
			<geometry>
				<mesh filename="../Collision/BaseLink.stl" />
			</geometry>
		</collision>
	</link>
	<link name="Link1">
		<visual>
			<origin rpy="0.000 -0.000 0.000" xyz="0.000 0.000 0.000" />
			<geometry>
				<mesh filename="../Visual/Link1.stl" />
			</geometry>
			<material name="ABBWhite" />
		</visual>
		<collision>
			<origin rpy="0.000 -0.000 0.000" xyz="0.000 0.000 0.000" />
			<geometry>
				<mesh filename="../Collision/Link1.stl" />
			</geometry>
		</collision>
	</link>
	<link name="Link2">
		<visual>
			<origin rpy="0.000 -0.000 0.000" xyz="0.000 0.000 0.000" />
			<geometry>
				<mesh filename="../Visual/Link2.stl" />
			</geometry>
			<material name="ABBWhite" />
		</visual>
		<collision>
			<origin rpy="0.000 -0.000 0.000" xyz="0.000 0.000 0.000" />
			<geometry>
				<mesh filename="../Collision/Link2.stl" />
			</geometry>
		</collision>
	</link>
	<link name="Link3">
		<visual>
			<origin rpy="0.000 -0.000 0.000" xyz="0.000 0.000 0.000" />
			<geometry>
				<mesh filename="../Visual/Link3.stl" />
			</geometry>
			<material name="ABBWhite" />
		</visual>
		<collision>
			<origin rpy="0.000 -0.000 0.000" xyz="0.000 0.000 0.000" />
			<geometry>
				<mesh filename="../Collision/Link3.stl" />
			</geometry>
		</collision>
	</link>
	<link name="Link4">
		<visual>
			<origin rpy="0.000 -0.000 0.000" xyz="0.000 0.000 0.000" />
			<geometry>
				<mesh filename="../Visual/Link4.stl" />
			</geometry>
			<material name="ABBWhite" />
		</visual>
		<collision>
			<origin rpy="0.000 -0.000 0.000" xyz="0.000 0.000 0.000" />
			<geometry>
				<mesh filename="../Collision/Link4.stl" />
			</geometry>
		</collision>
	</link>
	<link name="Link5">
		<visual>
			<origin rpy="0.000 -0.000 0.000" xyz="0.000 0.000 0.000" />
			<geometry>
				<mesh filename="../Visual/Link5.stl" />
			</geometry>
			<material name="ABBWhite" />
		</visual>
		<collision>
			<origin rpy="0.000 -0.000 0.000" xyz="0.000 0.000 0.000" />
			<geometry>
				<mesh filename="../Collision/Link5.stl" />
			</geometry>
		</collision>
	</link>
	<link name="Link6">
		<visual>
			<origin rpy="0.000 -0.000 0.000" xyz="0.000 0.000 0.000" />
			<geometry>
				<mesh filename="../Visual/Link6.stl" />
			</geometry>
			<material name="ABBBlack" />
		</visual>
		<collision>
			<origin rpy="0.000 -0.000 0.000" xyz="0.000 0.000 0.000" />
			<geometry>
				<mesh filename="../Collision/Link6.stl" />
			</geometry>
		</collision>
	</link>
	<link name="ee_link" />
    <!-- end of link list -->

    <!-- joint list -->
	<joint name="Joint1" type="revolute">
		<axis xyz="0.000 0.000 1.000" />
		<parent link="base_link" />
		<child link="Link1" />
		<origin rpy="0.000 -0.000 0.000" xyz="0.000 0.000 0.000" />
		<limit acceleration="13.09" effort="0.0" lower="-2.8597" upper="2.85979" velocity="2.618" />
	</joint>
	<joint name="Joint2" type="revolute">
		<axis xyz="0.000 1.000 0.000" />
		<parent link="Link1" />
		<child link="Link2" />
		<origin rpy="0.000 -0.000 0.000" xyz="0.200 0.000 0.680" />
		<limit acceleration="10.472" effort="0.0" lower="-1.2017" upper="1.638" velocity="2.0944" />
	</joint>
	<joint name="Joint3" type="revolute">
		<axis xyz="0.000 1.000 0.000" />
		<parent link="Link2" />
		<child link="Link3" />
		<origin rpy="0.000 -0.000 0.000" xyz="0.000 0.000 0.890" />
		<limit acceleration="10.472" effort="0.0" lower="-1.0272" upper="1.1145" velocity="2.0944" />
	</joint>
	<joint name="Joint4" type="revolute">
		<axis xyz="1.000 0.000 0.000" />
		<parent link="Link3" />
		<child link="Link4" />
		<origin rpy="0.000 -0.000 0.000" xyz="1.380 0.000 0.150" />
		<limit acceleration="19.635" effort="0.0" lower="-3.47" upper="3.47" velocity="3.927" />
	</joint>
	<joint name="Joint5" type="revolute">
		<axis xyz="0.000 1.000 0.000" />
		<parent link="Link4" />
		<child link="Link5" />
		<origin rpy="0.000 -0.000 0.000" xyz="0.000 0.000 0.000" />
		<limit acceleration="21.8164" effort="0.0" lower="-2.0744" upper="2.0744" velocity="4.3633" />
	</joint>
	<joint name="Joint6" type="revolute">
		<axis xyz="1.000 0.000 0.000" />
		<parent link="Link5" />
		<child link="Link6" />
		<origin rpy="0.000 -0.000 0.000" xyz="0.00 0.000 0.000" />
		<limit acceleration="28.798" effort="0.0" lower="-6.9613" upper="6.96130" velocity="5.7596" />
	</joint>

	<joint name="jointEE" type="fixed">
		<parent link="Link6" />
		<child link="ee_link" />
		<origin rpy="0.000 1.570796327 0.000" xyz="0.14 0.000 0.000" />
	</joint>
    <!-- end of joint list -->

</robot>