<?xml version='1.0' encoding='utf-8'?>
<robot name="ABB_IRB4600_20_250">
	<material name="ABBWhite">
		<color rgba="0.925 0.925 0.906 1.000" />
	</material>

    <!-- link list -->
	<link name="base_link">
		<visual>
			<origin rpy="0.000 -0.000 0.000" xyz="0.000 0.000 0.000" />
			<geometry>
				<mesh filename="Visual/BaseLink.dae" />
			</geometry>
			<material name="ABBWhite" />
		</visual>
		<collision>
			<origin rpy="0.000 -0.000 0.000" xyz="0.000 0.000 0.000" />
			<geometry>
				<mesh filename="Collision/BaseLink.stl" />
			</geometry>
		</collision>
	</link>
	<link name="Link1">
		<visual>
			<origin rpy="0.000 -0.000 0.000" xyz="0.000 0.000 0.000" />
			<geometry>
				<mesh filename="Visual/Link1.dae" />
			</geometry>
			<material name="ABBWhite" />
		</visual>
		<collision>
			<origin rpy="0.000 -0.000 0.000" xyz="0.000 0.000 0.000" />
			<geometry>
				<mesh filename="Collision/Link1.stl" />
			</geometry>
		</collision>
	</link>
	<link name="Link2">
		<visual>
			<origin rpy="0.000 -0.000 0.000" xyz="0.000 0.000 0.000" />
			<geometry>
				<mesh filename="Visual/Link2.dae" />
			</geometry>
			<material name="ABBWhite" />
		</visual>
		<collision>
			<origin rpy="0.000 -0.000 0.000" xyz="0.000 0.000 0.000" />
			<geometry>
				<mesh filename="Collision/Link2.stl" />
			</geometry>
		</collision>
	</link>
	<link name="Link3">
		<visual>
			<origin rpy="0.000 -0.000 0.000" xyz="0.000 0.000 0.000" />
			<geometry>
				<mesh filename="Visual/Link3.dae" />
			</geometry>
			<material name="ABBWhite" />
		</visual>
		<collision>
			<origin rpy="0.000 -0.000 0.000" xyz="0.000 0.000 0.000" />
			<geometry>
				<mesh filename="Collision/Link3.stl" />
			</geometry>
		</collision>
	</link>
	<link name="Link4">
		<visual>
			<origin rpy="0.000 -0.000 0.000" xyz="0.000 0.000 0.000" />
			<geometry>
				<mesh filename="Visual/Link4.dae" />
			</geometry>
			<material name="ABBWhite" />
		</visual>
		<collision>
			<origin rpy="0.000 -0.000 0.000" xyz="0.000 0.000 0.000" />
			<geometry>
				<mesh filename="Collision/Link4.stl" />
			</geometry>
		</collision>
	</link>
	<link name="Link5">
		<visual>
			<origin rpy="0.000 -0.000 0.000" xyz="0.000 0.000 0.000" />
			<geometry>
				<mesh filename="Visual/Link5.dae" />
			</geometry>
			<material name="ABBWhite" />
		</visual>
		<collision>
			<origin rpy="0.000 -0.000 0.000" xyz="0.000 0.000 0.000" />
			<geometry>
				<mesh filename="Collision/Link5.stl" />
			</geometry>
		</collision>
	</link>
	<link name="Link6">
		<visual>
			<origin rpy="0.000 -0.000 0.000" xyz="0.000 0.000 0.000" />
			<geometry>
				<mesh filename="Visual/Link6.dae" />
			</geometry>
			<material name="ABBWhite" />
		</visual>
		<collision>
			<origin rpy="0.000 -0.000 0.000" xyz="0.000 0.000 0.000" />
			<geometry>
				<mesh filename="Collision/Link6.stl" />
			</geometry>
		</collision>
	</link>
	<link name="ee_link" />
    <!-- end of link list -->

    <!-- joint list -->
	<joint name="Joint1" type="revolute">
		<axis xyz="0.000 0.000 1.000" />
		<parent link="base_link" />
		<child link="Link1" />
		<origin rpy="0.000 -0.000 0.000" xyz="0.000 0.000 0.495" />
		<limit acceleration="15.2716" effort="0.0" lower="-3.1215" upper="3.12159" velocity="3.05432" />
	</joint>
	<joint name="Joint2" type="revolute">
		<axis xyz="0.000 1.000 0.000" />
		<parent link="Link1" />
		<child link="Link2" />
		<origin rpy="0.000 -0.000 0.000" xyz="0.175 0.000 0.000" />
		<limit acceleration="15.2716" effort="0.0" lower="-1.5507" upper="2.59799" velocity="3.05432" />
	</joint>
	<joint name="Joint3" type="revolute">
		<axis xyz="0.000 1.000 0.000" />
		<parent link="Link2" />
		<child link="Link3" />
		<origin rpy="0.000 -0.000 0.000" xyz="0.000 0.000 1.095" />
		<limit acceleration="15.2716" effort="0.0" lower="-3.1215" upper="1.28899" velocity="3.05432" />
	</joint>
	<joint name="Joint4" type="revolute">
		<axis xyz="1.000 0.000 0.000" />
		<parent link="Link3" />
		<child link="Link4" />
		<origin rpy="0.000 -0.000 0.000" xyz="0.000 0.000 0.175" />
		<limit acceleration="31.4159" effort="0.0" lower="-6.9613" upper="6.96131" velocity="6.28318" />
	</joint>
	<joint name="Joint5" type="revolute">
		<axis xyz="0.000 1.000 0.000" />
		<parent link="Link4" />
		<child link="Link5" />
		<origin rpy="0.000 -0.000 0.000" xyz="1.230 0.000 0.000" />
		<limit acceleration="31.4159" effort="0.0" lower="-2.1616" upper="2.07439" velocity="6.28318" />
	</joint>
	<joint name="Joint6" type="revolute">
		<axis xyz="1.000 0.000 0.000" />
		<parent link="Link5" />
		<child link="Link6" />
		<origin rpy="0.000 -0.000 0.000" xyz="0.085 0.000 0.000" />
		<limit acceleration="43.6332" effort="0.0" lower="-6.9613" upper="6.96131" velocity="8.72664" />
	</joint>
	<joint name="jointEE" type="fixed">
		<parent link="Link6" />
		<child link="ee_link" />
		<origin rpy="0.000 1.570796327 0.000" xyz="0.000 0.000 0.000" />
	</joint>
    <!-- end of joint list -->

</robot>